<?xml version="1.0" encoding="utf-8"?>
<!-- This URDF was automatically created by SolidWorks to URDF Exporter! Originally created by Stephen Brawner (brawner@gmail.com) 
     Commit Version: 1.6.0-4-g7f85cfe  Build Version: 1.6.7995.38578
     For more information, please see http://wiki.ros.org/sw_urdf_exporter -->
<robot
  name="LunarAgv">
  <link
    name="base_link">
    <inertial>
      <origin
        xyz="-0.00015288 0.16922 0.84844"
        rpy="0 0 0" />
      <mass
        value="1127.4" />
      <inertia
        ixx="186.65"
        ixy="-0.071893"
        ixz="0.00075936"
        iyy="177.73"
        iyz="0.034507"
        izz="267.97" />
    </inertial>
    <visual>
      <origin
        xyz="0 0 0"
        rpy="0 0 0" />
      <geometry>
        <mesh
          filename="package://LunarAgv/meshes/base_link.STL" />
      </geometry>
      <material
        name="">
        <color
          rgba="0.77647 0.75686 0.73725 1" />
      </material>
    </visual>
    <collision>
      <origin
        xyz="0 0 0"
        rpy="0 0 0" />
      <geometry>
        <mesh
          filename="package://LunarAgv/meshes/base_link.STL" />
      </geometry>
    </collision>
  </link>



  <link
    name="front_left_wheel_link">
    <inertial>
      <origin
        xyz="-0.486288529907035 0.805369363781165 -0.568713052187755"
        rpy="0 0 0" />
      <mass
        value="1420.1834445863" />
      <inertia
        ixx="951.6948212748"
        ixy="21.3714554780942"
        ixz="-0.98750627442229"
        iyy="810.047713827878"
        iyz="-16.2698367458512"
        izz="1015.9248300136" />
    </inertial>
    <visual>
      <origin
        xyz="0 0 0"
        rpy="0 0 0" />
      <geometry>
        <mesh
          filename="package://LunarAgv/meshes/front_left_wheel_link.STL" />
      </geometry>
      <material
        name="">
        <color
          rgba="1 1 1 1" />
      </material>
    </visual>
    <collision>
      <origin
        xyz="0 0 0"
        rpy="0 0 0" />
      <geometry>
        <mesh
          filename="package://LunarAgv/meshes/front_left_wheel_link.STL" />
      </geometry>
    </collision>
  </link>
  <joint
    name="front_left_wheel_joint"
    type="continuous">
    <origin
      xyz="0.56625 -0.125 -0.762"
      rpy="1.5708 0 1.5708" />
    <parent
      link="base_link" />
    <child
      link="front_left_wheel_link" />
    <axis
      xyz="0 0 1" />
  </joint>


  <link
    name="front_right_wheel_link">
    <inertial>
      <origin
        xyz="0.486288529907022 0.811369363781171 -0.563786947812247"
        rpy="0 0 0" />
      <mass
        value="1420.1834445863" />
      <inertia
        ixx="951.6948212748"
        ixy="-21.3714554780943"
        ixz="-0.98750627442239"
        iyy="810.047713827877"
        iyz="16.2698367458499"
        izz="1015.9248300136" />
    </inertial>
    <visual>
      <origin
        xyz="0 0 0"
        rpy="0 0 0" />
      <geometry>
        <mesh
          filename="package://LunarAgv/meshes/front_right_wheel_link.STL" />
      </geometry>
      <material
        name="">
        <color
          rgba="1 1 1 1" />
      </material>
    </visual>
    <collision>
      <origin
        xyz="0 0 0"
        rpy="0 0 0" />
      <geometry>
        <mesh
          filename="package://LunarAgv/meshes/front_right_wheel_link.STL" />
      </geometry>
    </collision>
  </link>
  <joint
    name="front_right_wheel_joint"
    type="continuous">
    <origin
      xyz="-0.56625 -0.125 -0.768"
      rpy="1.5708 0 -1.5708" />
    <parent
      link="base_link" />
    <child
      link="front_right_wheel_link" />
    <axis
      xyz="0 0 1" />
  </joint>




  <link
    name="back_left_wheel_link">
    <inertial>
      <origin
        xyz="-0.486288529907001 -0.724630636218818 -0.568713052187753"
        rpy="0 0 0" />
      <mass
        value="1420.1834445863" />
      <inertia
        ixx="951.6948212748"
        ixy="21.3714554780943"
        ixz="-0.987506274422062"
        iyy="810.047713827877"
        iyz="-16.2698367458515"
        izz="1015.9248300136" />
    </inertial>
    <visual>
      <origin
        xyz="0 0 0"
        rpy="0 0 0" />
      <geometry>
        <mesh
          filename="package://LunarAgv/meshes/back_left_wheel_link.STL" />
      </geometry>
      <material
        name="">
        <color
          rgba="1 1 1 1" />
      </material>
    </visual>
    <collision>
      <origin
        xyz="0 0 0"
        rpy="0 0 0" />
      <geometry>
        <mesh
          filename="package://LunarAgv/meshes/back_left_wheel_link.STL" />
      </geometry>
    </collision>
  </link>
  <joint
    name="back_left_wheel_joint"
    type="continuous">
    <origin
      xyz="0.56625 -0.125 0.768"
      rpy="1.5708 0 1.5708" />
    <parent
      link="base_link" />
    <child
      link="back_left_wheel_link" />
    <axis
      xyz="0 0 1" />
  </joint>

  
  <link
    name="back_right_wheel_link">
    <inertial>
      <origin
        xyz="0.486288529907021 -0.712682613755943 -0.571335071854233"
        rpy="0 0 0" />
      <mass
        value="1420.1834445863" />
      <inertia
        ixx="951.6948212748"
        ixy="-21.3599051194888"
        ixz="-1.21191220004488"
        iyy="809.728684697972"
        iyz="14.1040778112797"
        izz="1016.24385914351" />
    </inertial>
    <visual>
      <origin
        xyz="0 0 0"
        rpy="0 0 0" />
      <geometry>
        <mesh
          filename="package://LunarAgv/meshes/back_right_wheel_link.STL" />
      </geometry>
      <material
        name="">
        <color
          rgba="1 1 1 1" />
      </material>
    </visual>
    <collision>
      <origin
        xyz="0 0 0"
        rpy="0 0 0" />
      <geometry>
        <mesh
          filename="package://LunarAgv/meshes/back_right_wheel_link.STL" />
      </geometry>
    </collision>
  </link>
  <joint
    name="back_right_wheel_joint"
    type="continuous">
    <origin
      xyz="-0.56628 -0.125 0.76201"
      rpy="1.5603 0 -1.5708" />
    <parent
      link="base_link" />
    <child
      link="back_right_wheel_link" />
    <axis
      xyz="0 0 1" />
  </joint>
  <link
    name="front_lidar_link">
    <inertial>
      <origin
        xyz="-0.798515021205427 -1.04550202779012 0.242075134496693"
        rpy="0 0 0" />
      <mass
        value="9.49883099957734" />
      <inertia
        ixx="0.0179386353992628"
        ixy="0.000278287807681088"
        ixz="-0.000125674026995603"
        iyy="0.018007426390983"
        iyz="-8.78195059417083E-05"
        izz="0.0132377001479147" />
    </inertial>
    <visual>
      <origin
        xyz="0 0 0"
        rpy="0 0 0" />
      <geometry>
        <mesh
          filename="package://LunarAgv/meshes/front_lidar_link.STL" />
      </geometry>
      <material
        name="">
        <color
          rgba="0.529411764705882 0.549019607843137 0.549019607843137 1" />
      </material>
    </visual>
    <collision>
      <origin
        xyz="0 0 0"
        rpy="0 0 0" />
      <geometry>
        <mesh
          filename="package://LunarAgv/meshes/front_lidar_link.STL" />
      </geometry>
    </collision>
  </link>
  <joint
    name="front_lidar_joint"
    type="fixed">
    <origin
      xyz="0.042822 -0.033127 -0.077997"
      rpy="1.5708 0.088182 0" />
    <parent
      link="base_link" />
    <child
      link="front_lidar_link" />
    <axis
      xyz="0 0 0" />
  </joint>
  <link
    name="back_lidar_link">
    <inertial>
      <origin
        xyz="-0.798515018850648 -1.04550202621823 0.242075132431624"
        rpy="0 0 0" />
      <mass
        value="9.49883135601028" />
      <inertia
        ixx="0.0179386354025894"
        ixy="0.000278287590566171"
        ixz="-0.000125674029820003"
        iyy="0.0180074270140846"
        iyz="-8.78194817377976E-05"
        izz="0.0132377007863435" />
    </inertial>
    <visual>
      <origin
        xyz="0 0 0"
        rpy="0 0 0" />
      <geometry>
        <mesh
          filename="package://LunarAgv/meshes/back_lidar_link.STL" />
      </geometry>
      <material
        name="">
        <color
          rgba="0.529411764705882 0.549019607843137 0.549019607843137 1" />
      </material>
    </visual>
    <collision>
      <origin
        xyz="0 0 0"
        rpy="0 0 0" />
      <geometry>
        <mesh
          filename="package://LunarAgv/meshes/back_lidar_link.STL" />
      </geometry>
    </collision>
  </link>
  <joint
    name="back_lidar_joint"
    type="fixed">
    <origin
      xyz="-0.059817 -0.033127 0.093822"
      rpy="-1.5708 -0.10576 3.1416" />
    <parent
      link="base_link" />
    <child
      link="back_lidar_link" />
    <axis
      xyz="0 0 0" />
  </joint>
  <link
    name="code_camera_link">
    <inertial>
      <origin
        xyz="-0.0013803730667627 3.56653121648981E-07 -0.0187241189967535"
        rpy="0 0 0" />
      <mass
        value="0.241766943453364" />
      <inertia
        ixx="0.000139044768283738"
        ixy="-3.4831582113527E-09"
        ixz="-7.95697315906295E-07"
        iyy="0.000153218163720174"
        iyz="1.2072362600808E-09"
        izz="0.00019399978647261" />
    </inertial>
    <visual>
      <origin
        xyz="0 0 0"
        rpy="0 0 0" />
      <geometry>
        <mesh
          filename="package://LunarAgv/meshes/code_camera_link.STL" />
      </geometry>
      <material
        name="">
        <color
          rgba="0.792156862745098 0.819607843137255 0.933333333333333 1" />
      </material>
    </visual>
    <collision>
      <origin
        xyz="0 0 0"
        rpy="0 0 0" />
      <geometry>
        <mesh
          filename="package://LunarAgv/meshes/code_camera_link.STL" />
      </geometry>
    </collision>
  </link>
  <joint
    name="code_camera_joint"
    type="fixed">
    <origin
      xyz="0 -0.11168 0"
      rpy="1.5708 -1.5708 0" />
    <parent
      link="base_link" />
    <child
      link="code_camera_link" />
    <axis
      xyz="0 0 0" />
  </joint>
</robot>