<?xml version="1.0" ?>
<!-- =================================================================================== -->
<!-- |    This document was autogenerated by xacro from /home/space/work/gazebo_ws/src/lunarPrinter/urdf/arm/arm.xacro | -->
<!-- |    EDITING THIS FILE BY HAND IS NOT RECOMMENDED                                 | -->
<!-- =================================================================================== -->
<robot name="arm">
    <!--#############################################-->
    <!-- 构建基座 -->
    <!--#############################################-->
    <link name="arm_base_link">
        <inertial>
            <origin rpy="0 0 0" xyz="-7.89007780837018E-05 0.0260795471385364 0.000250283055826241" />
            <mass value="0.168400023612511" />
            <inertia ixx="0.00175634288446034" ixy="-0.0705111471416143E-06" ixz="0.00000132536380514416" iyy="0.00339920630895577" iyz="0.0212062962173668E-05" izz="0.00175097307372981" />
        </inertial>
        <visual>
            <origin rpy="0 0 0" xyz="0 0 0" />
            <geometry>
                <mesh filename="package:// lunarPrinter/meshes/arm/base_link.STL" />
            </geometry>
            <material name="Blue">
                <color rgba="0 0 1 1" />
            </material>
        </visual>
        <collision>
            <origin rpy="0 0 0" xyz="0 0 0" />
            <geometry>
                <mesh filename="package:// lunarPrinter/meshes/arm/base_link.STL" />
            </geometry>
        </collision>
    </link>
    <!-- 设置关节坐标系 -->
    
    <link name="world"/>
    <joint name="fixed"  type="fixed">
        <origin xyz="0 0 1" rpy="0 0 0" />
        <parent link="world"/>
        <child link="arm_base_link"/>
    </joint>
   
    <!--#############################################-->
    <!-- 构建关节一 -->
    <!--#############################################-->
    <link name="link_1">
        <inertial>
            <origin rpy="0 0 0" xyz="0.0240592930415565 0.147960202341401 0.150275212212244" />
            <mass value="0.461935755619436" />
            <inertia ixx="0.00182892351491963" ixy="-0.00000106097607947388" ixz="0.0293650425485005E-06" iyy="0.00139480004434281" iyz="-0.0728873034095655E-05" izz="0.00155379054418068" />
        </inertial>
        <visual>
            <origin rpy="0 0 0" xyz="0 0 0" />
            <geometry>
                <mesh filename="package:// lunarPrinter/meshes/arm/link_1.STL" />
            </geometry>
            <material name="While">
                <color rgba="1 1 1 0.95" />
            </material>
        </visual>
        <collision>
            <origin rpy="0 0 0" xyz="0 0 0" />
            <geometry>
                <mesh filename="package:// lunarPrinter/meshes/arm/link_1.STL" />
            </geometry>
        </collision>
    </link>
    <joint name="joint_1" type="revolute">
        <origin rpy="0 0 3.1416" xyz="0 0 0.054" />
        <parent link="arm_base_link" />
        <child link="link_1" />
        <axis xyz="0 0 1" />
        <limit effort="20" lower="-6.2831853" upper="6.2831853" velocity="2.0943951" />
    </joint>
    <!--#############################################-->
    <!-- 构建关节二 -->
    <!--#############################################-->
    <link name="link_2">
        <inertial>
            <origin rpy="0 0 0" xyz="-0.00741058119634522 0.838316036295861 0.102815693133785" />
            <mass value="0.242374252720559" />
            <inertia ixx="0.01249" ixy="0.0000015288" ixz="-0.000026305" iyy="0.0020173" iyz="0.000030011" izz="0.012505" />
        </inertial>
        <visual>
            <origin rpy="0 0 0" xyz="0 0 0" />
            <geometry>
                <mesh filename="package:// lunarPrinter/meshes/arm/link_2.STL" />
            </geometry>
            <material name="Blue">
                <color rgba="0 0 1 1" />
            </material>
        </visual>
        <collision>
            <origin rpy="0 0 0" xyz="0 0 0" />
            <geometry>
                <mesh filename="package:// lunarPrinter/meshes/arm/link_2.STL" />
            </geometry>
        </collision>
    </link>
    <!--
    <joint name="joint_2" type="fixed">
        <origin xyz="0 0.164 0" rpy="1.5708 -1.5708 3.1416" />
        <parent link="link_1" />
        <child link="link_2" />
    </joint>
    -->
    <joint name="joint_2" type="revolute">
        <origin rpy="1.5708 0 1.5686" xyz="0.11845 0.19974 0.175" />
        /&gt;
        <parent link="link_1" />
        <child link="link_2" />
        <axis xyz="0 0 1" />
        <limit effort="50" lower="-3.14159265" upper="3.14159265" velocity="2.0943951" />
    </joint>
    <!--#############################################-->
    <!-- 构建关节三 -->
    <!--#############################################-->
    <link name="link_3">
        <inertial>
            <origin rpy="0 0 0" xyz="0.260661701543515 0.086562345757625 0.0904582129864851" />
            <mass value="0.415021573008086" />
            <inertia ixx="0.00448434081189012" ixy="-0.00305014121987798" ixz="-0.000391459265336423" iyy="0.00893193211636663" iyz="-0.000138785013334083" izz="0.0110643474031866" />
        </inertial>
        <visual>
            <origin rpy="0 0 0" xyz="0 0 0" />
            <geometry>
                <mesh filename="package:// lunarPrinter/meshes/arm/link_3.STL" />
            </geometry>
            <material name="While">
                <color rgba="1 1 1 0.95" />
            </material>
        </visual>
        <collision>
            <origin rpy="0 0 0" xyz="0 0 0" />
            <geometry>
                <mesh filename="package:// lunarPrinter/meshes/arm/link_3.STL" />
            </geometry>
        </collision>
    </link>
    <!--
    <joint name="joint_3" type="fixed">
        <origin xyz="0.608 0 0" rpy="0 0 0" />
        <parent link="link_2" />
        <child link="link_3" />
    </joint>
    -->
    <joint name="joint_3" type="revolute">
        <origin rpy="3.1416 0 0" xyz="-0.0080695 1.65 0.003" />
        <parent link="link_2" />
        <child link="link_3" />
        <axis xyz="0 0 1" />
        <limit effort="50" lower="-3.14159265" upper="3.14159265" velocity="3.14159265" />
    </joint>
    <!--#############################################-->
    <!-- 构建关节四 -->
    <!--#############################################-->
    <link name="link_4">
        <inertial>
            <origin rpy="0 0 0" xyz="-0.0031147 -0.00083318 0.090676" />
            <mass value="0.041922" />
            <inertia ixx="0.00022992" ixy="0.019927E-06" ixz="-0.027983E-05" iyy="0.00016034" iyz="0.028486E-06" izz="0.00012089" />
        </inertial>
        <visual>
            <origin rpy="0 0 0" xyz="0 0 0" />
            <geometry>
                <mesh filename="package:// lunarPrinter/meshes/arm/link_4.STL" />
            </geometry>
            <material name="Blue">
                <color rgba="0 0 1 1" />
            </material>
        </visual>
        <collision>
            <origin rpy="0 0 0" xyz="0 0 0" />
            <geometry>
                <mesh filename="package:// lunarPrinter/meshes/arm/link_4.STL" />
            </geometry>
        </collision>
    </link>
    <!--
    <joint name="joint_4" type="fixed">
        <origin xyz="0.566 0 0" rpy="0 0 1.5708" />
        <parent link="link_3" />
        <child link="link_4" />
    </joint>
    -->
    <joint name="joint_4" type="revolute">
        <origin rpy="0.50789 -1.5708 3.14159265" xyz="1.5248 0.74569 0.1255" />
        <parent link="link_3" />
        <child link="link_4" />
        <axis xyz="0 0 1" />
        <limit effort="10" lower="-6.2831853" upper="6.2831853" velocity="3.14159265" />
    </joint>
    <!--#############################################-->
    <!-- 构建关节五 -->
    <!--#############################################-->
    <link name="link_5">
        <inertial>
            <origin xyz="-5.13810008009319E-05 0.0631532787550311 0.0576399105925339" rpy="0 0 0" />
            <mass value="0.025" />
            <inertia ixx="0.000034092146499895" ixy="0.0354033055425707E-07" ixz="-0.0226564220026257E-06" iyy="0.0000396941822314873" iyz="-0.00000131806839548867" izz="0.0000295296609100218" />
        </inertial>
        <visual>
            <origin rpy="0 0 0" xyz="0 0 0" />
            <geometry>
                <mesh filename="package:// lunarPrinter/meshes/arm/link_5.STL" />
            </geometry>
            <material name="While">
                <color rgba="1 1 1 0.95" />
            </material>
        </visual>
        <collision>
            <origin rpy="0 0 0" xyz="0 0 0" />
            <geometry>
                <mesh filename="package:// lunarPrinter/meshes/arm/link_5.STL" />
            </geometry>
        </collision>
    </link>
    <joint name="joint_5" type="revolute">
        <origin rpy="1.5708 -1.0629 1.5708" xyz="-0.0615 0 0.167" />
        <parent link="link_4" />
        <child link="link_5" />
        <axis xyz="0 0 1" />
        <limit effort="5" lower="-6.2831853" upper="6.2831853" velocity="3.14159265" />
    </joint>
    <!--
    <joint name="joint_5" type="fixed">
        <origin xyz="0 -0.126 0" rpy="1.5708 0 0" />
        <parent link="link_4" />
        <child link="link_5" />
    </joint>
    -->
    <!--#############################################-->
    <!-- 构建关节六 -->
    <!--#############################################-->
    <link name="link_6">
        <inertial>
            <origin rpy="0 0 0" xyz="-7.78457159844592E-17 -2.1094237467878E-14 -0.0648864905098758" />
            <mass value="0.2" />
            <inertia ixx="0.0006352" ixy="-2.1853E-08" ixz="-5.0851E-09" iyy="0.00063521" iyz="-6.8675E-10" izz="0.0005861" />
        </inertial>
        <visual>
            <origin rpy="0 0 0" xyz="0 0 0" />
            <geometry>
                <mesh filename="package:// lunarPrinter/meshes/arm/link_6.STL" />
            </geometry>
            <material name="Blue">
                <color rgba="0 0 1 1" />
            </material>
        </visual>
        <collision>
            <origin rpy="0 0 0" xyz="0 0 0" />
            <geometry>
                <mesh filename="package:// lunarPrinter/meshes/arm/link_6.STL" />
            </geometry>
        </collision>
    </link>
    <joint name="joint_6" type="revolute">
        <origin rpy="-1.5708 1.5686 0" xyz="0 0.2856 0.0615" />
        <parent link="link_5" />
        <child link="link_6" />
        <axis xyz="0 0 1" />
        <limit effort="5" lower="-6.2831853" upper="6.2831853" velocity="3.14159265" />
    </joint>
    <!--
    <joint name="joint_6" type="fixed">
        <origin xyz="0 0.113 0" rpy="-1.5708 0 0" />
        <parent link="link_5" />
        <child link="link_6" />
    </joint>
    -->
    <!--#############################################-->
    <!-- 控制-->
    <!--#############################################-->
    <gazebo>
        <plugin filename="libgazebo_ros_control.so" name="gazebo_ros_control">
            <robotNamespace>/</robotNamespace>
            <controlPeriod>0.001</controlPeriod>
            <robotSimType>gazebo_ros_control/DefaultRobotHWSim</robotSimType>
            <legacyMode>false</legacyMode>
        </plugin>
    </gazebo>
    <gazebo reference="base_link">
        <material>Gazebo/DarkGrey</material>
    </gazebo>
    <!--
    <gazebo reference="link_1">
        <material>Gazebo/FlatBlack</material>
    </gazebo>
    -->
    <gazebo reference="link_2">
        <material>Gazebo/DarkGrey</material>
    </gazebo>
    <!--
    <gazebo reference="link_3">
        <material>Gazebo/FlatBlack</material>
    </gazebo>
    -->
    <gazebo reference="link_4">
        <material>Gazebo/DarkGrey</material>
    </gazebo>
    <!--
    <gazebo reference="link_5">
        <material>Gazebo/FlatBlack</material>
    </gazebo>
    -->
    <gazebo reference="link_6">
        <material>Gazebo/DarkGrey</material>
    </gazebo>
    <transmission name="joint_1_trans">
        <type>transmission_interface/SimpleTransmission</type>
        <joint name="joint_1">
            <hardwareInterface>hardware_interface/EffortJointInterface</hardwareInterface>
        </joint>
        <actuator name="joint_1_motor">
            <mechanicalReduction>1</mechanicalReduction>
            <hardwareInterface>hardware_interface/EffortJointInterface</hardwareInterface>
        </actuator>
    </transmission>
    <transmission name="joint_2_trans">
        <type>transmission_interface/SimpleTransmission</type>
        <joint name="joint_2">
            <hardwareInterface>hardware_interface/EffortJointInterface</hardwareInterface>
        </joint>
        <actuator name="joint_2_motor">
            <mechanicalReduction>1</mechanicalReduction>
            <hardwareInterface>hardware_interface/EffortJointInterface</hardwareInterface>
        </actuator>
    </transmission>
    <transmission name="joint_3_trans">
        <type>transmission_interface/SimpleTransmission</type>
        <joint name="joint_3">
            <hardwareInterface>hardware_interface/EffortJointInterface</hardwareInterface>
        </joint>
        <actuator name="joint_3_motor">
            <mechanicalReduction>1</mechanicalReduction>
            <hardwareInterface>hardware_interface/EffortJointInterface</hardwareInterface>
        </actuator>
    </transmission>
    <transmission name="joint_4_trans">
        <type>transmission_interface/SimpleTransmission</type>
        <joint name="joint_4">
            <hardwareInterface>hardware_interface/EffortJointInterface</hardwareInterface>
        </joint>
        <actuator name="joint_4_motor">
            <mechanicalReduction>1</mechanicalReduction>
            <hardwareInterface>hardware_interface/EffortJointInterface</hardwareInterface>
        </actuator>
    </transmission>
    <transmission name="joint_5_trans">
        <type>transmission_interface/SimpleTransmission</type>
        <joint name="joint_5">
            <hardwareInterface>hardware_interface/EffortJointInterface</hardwareInterface>
        </joint>
        <actuator name="joint_5_motor">
            <mechanicalReduction>1</mechanicalReduction>
            <hardwareInterface>hardware_interface/EffortJointInterface</hardwareInterface>
        </actuator>
    </transmission>
    <transmission name="joint_6_trans">
        <type>transmission_interface/SimpleTransmission</type>
        <joint name="joint_6">
            <hardwareInterface>hardware_interface/EffortJointInterface</hardwareInterface>
        </joint>
        <actuator name="joint_6_motor">
            <mechanicalReduction>1</mechanicalReduction>
            <hardwareInterface>hardware_interface/EffortJointInterface</hardwareInterface>
        </actuator>
    </transmission>
</robot>

