<?xml version="1.0" encoding="utf-8"?>
<!-- This URDF was automatically created by SolidWorks to URDF Exporter! Originally created by Stephen Brawner (brawner@gmail.com) 
     Commit Version: 1.6.0-4-g7f85cfe  Build Version: 1.6.7995.38578
     For more information, please see http://wiki.ros.org/sw_urdf_exporter -->
<robot
  name="lunarArm">
  <link
    name="base_link">
    <inertial>
      <origin
        xyz="0.00025028 -7.8901E-05 0.02608"
        rpy="0 0 0" />
      <mass
        value="16.84" />
      <inertia
        ixx="0.1751"
        ixy="0.00013254"
        ixz="2.1206E-05"
        iyy="0.17563"
        iyz="-7.0511E-06"
        izz="0.33992" />
    </inertial>
    <visual>
      <origin
        xyz="0 0 0"
        rpy="0 0 0" />
      <geometry>
        <mesh
          filename="package://lunarArm/meshes/base_link.STL" />
      </geometry>
      <material
        name="">
        <color
          rgba="0.98824 0.73725 0.51765 1" />
      </material>
    </visual>
    <collision>
      <origin
        xyz="0 0 0"
        rpy="0 0 0" />
      <geometry>
        <mesh
          filename="package://lunarArm/meshes/base_link.STL" />
      </geometry>
    </collision>
  </link>
  <link
    name="link_1">
    <inertial>
      <origin
        xyz="0.14799 -0.024106 -0.024855"
        rpy="0 0 0" />
      <mass
        value="46.231" />
      <inertia
        ixx="0.13949"
        ixy="0.00010217"
        ixz="-7.2873E-05"
        iyy="0.1829"
        iyz="-2.943E-06"
        izz="0.1554" />
    </inertial>
    <visual>
      <origin
        xyz="0 0 0"
        rpy="0 0 0" />
      <geometry>
        <mesh
          filename="package://lunarArm/meshes/link_1.STL" />
      </geometry>
      <material
        name="">
        <color
          rgba="0.98824 0.73725 0.51765 1" />
      </material>
    </visual>
    <collision>
      <origin
        xyz="0 0 0"
        rpy="0 0 0" />
      <geometry>
        <mesh
          filename="package://lunarArm/meshes/link_1.STL" />
      </geometry>
    </collision>
  </link>
  <joint
    name="joint_1"
    type="revolute">
    <origin
      xyz="0 0 0.229"
      rpy="0 0 0" />
    <parent
      link="base_link" />
    <child
      link="link_1" />
    <axis
      xyz="0 0 1" />
    <limit
      lower="-6.2832"
      upper="6.2832"
      effort="0"
      velocity="0" />
  </joint>
  <link
    name="link_2">
    <inertial>
      <origin
        xyz="0.83834 0.0038061 0.22126"
        rpy="0 0 0" />
      <mass
        value="24.237" />
      <inertia
        ixx="0.20173"
        ixy="0.00014631"
        ixz="-0.0030013"
        iyy="1.249"
        iyz="0.0026338"
        izz="1.2505" />
    </inertial>
    <visual>
      <origin
        xyz="0 0 0"
        rpy="0 0 0" />
      <geometry>
        <mesh
          filename="package://lunarArm/meshes/link_2.STL" />
      </geometry>
      <material
        name="">
        <color
          rgba="0.46667 0.70196 1 1" />
      </material>
    </visual>
    <collision>
      <origin
        xyz="0 0 0"
        rpy="0 0 0" />
      <geometry>
        <mesh
          filename="package://lunarArm/meshes/link_2.STL" />
      </geometry>
    </collision>
  </link>
  <joint
    name="joint_2"
    type="revolute">
    <origin
      xyz="0.2 0 0"
      rpy="1.5708 -1.5708 0" />
    <parent
      link="link_1" />
    <child
      link="link_2" />
    <axis
      xyz="0 0 1" />
    <limit
      lower="-3.1416"
      upper="3.1416"
      effort="0"
      velocity="0" />
  </joint>
  <link
    name="link_3">
    <inertial>
      <origin
        xyz="0.033918 -0.061928 0.046646"
        rpy="0 0 0" />
      <mass
        value="28.763" />
      <inertia
        ixx="0.22343"
        ixy="0.028279"
        ixz="0.0068456"
        iyy="0.20045"
        iyz="-0.040769"
        izz="0.28282" />
    </inertial>
    <visual>
      <origin
        xyz="0 0 0"
        rpy="0 0 0" />
      <geometry>
        <mesh
          filename="package://lunarArm/meshes/link_3.STL" />
      </geometry>
      <material
        name="">
        <color
          rgba="0.98824 0.73725 0.51765 1" />
      </material>
    </visual>
    <collision>
      <origin
        xyz="0 0 0"
        rpy="0 0 0" />
      <geometry>
        <mesh
          filename="package://lunarArm/meshes/link_3.STL" />
      </geometry>
    </collision>
  </link>
  <joint
    name="joint_3"
    type="revolute">
    <origin
      xyz="1.65 0 0"
      rpy="0 0 0" />
    <parent
      link="link_2" />
    <child
      link="link_3" />
    <axis
      xyz="0 0 1" />
    <limit
      lower="-3.1416"
      upper="3.1416"
      effort="0"
      velocity="0" />
  </joint>
  <link
    name="link_4">
    <inertial>
      <origin
        xyz="0.00012024 -0.0034361 -0.79411"
        rpy="0 0 0" />
      <mass
        value="19.419" />
      <inertia
        ixx="0.86759"
        ixy="3.0378E-07"
        ixz="-2.8589E-06"
        iyy="0.87448"
        iyz="-0.0016904"
        izz="0.13274" />
    </inertial>
    <visual>
      <origin
        xyz="0 0 0"
        rpy="0 0 0" />
      <geometry>
        <mesh
          filename="package://lunarArm/meshes/link_4.STL" />
      </geometry>
      <material
        name="">
        <color
          rgba="0.46667 1 0.40392 1" />
      </material>
    </visual>
    <collision>
      <origin
        xyz="0 0 0"
        rpy="0 0 0" />
      <geometry>
        <mesh
          filename="package://lunarArm/meshes/link_4.STL" />
      </geometry>
    </collision>
  </link>
  <joint
    name="joint_4"
    type="revolute">
    <origin
      xyz="0.09 -1.8624 0"
      rpy="1.5708 0 0" />
    <parent
      link="link_3" />
    <child
      link="link_4" />
    <axis
      xyz="0 0 1" />
    <limit
      lower="-6.2832"
      upper="6.2832"
      effort="0"
      velocity="0" />
  </joint>
  <link
    name="link_5">
    <inertial>
      <origin
        xyz="-0.00035063 0.028134 0.0011422"
        rpy="0 0 0" />
      <mass
        value="1.4354" />
      <inertia
        ixx="0.0027564"
        ixy="1.0074E-08"
        ixz="-9.5125E-07"
        iyy="0.0026368"
        iyz="0.00013232"
        izz="0.0023676" />
    </inertial>
    <visual>
      <origin
        xyz="0 0 0"
        rpy="0 0 0" />
      <geometry>
        <mesh
          filename="package://lunarArm/meshes/link_5.STL" />
      </geometry>
      <material
        name="">
        <color
          rgba="0.078431 0.67059 0.50196 1" />
      </material>
    </visual>
    <collision>
      <origin
        xyz="0 0 0"
        rpy="0 0 0" />
      <geometry>
        <mesh
          filename="package://lunarArm/meshes/link_5.STL" />
      </geometry>
    </collision>
  </link>
  <joint
    name="joint_5"
    type="revolute">
    <origin
      xyz="0 0 0"
      rpy="1.5708 -1.5708 0" />
    <parent
      link="link_4" />
    <child
      link="link_5" />
    <axis
      xyz="0 0 1" />
    <limit
      lower="-3.1416"
      upper="1.5708"
      effort="0"
      velocity="0" />
  </joint>
  <link
    name="link_6">
    <inertial>
      <origin
        xyz="-0.00031751 0.00015612 -0.027775"
        rpy="0 0 0" />
      <mass
        value="1.1891" />
      <inertia
        ixx="0.00072168"
        ixy="-6.126E-07"
        ixz="-4.6657E-07"
        iyy="0.00072593"
        iyz="2.1358E-07"
        izz="0.0014041" />
    </inertial>
    <visual>
      <origin
        xyz="0 0 0"
        rpy="0 0 0" />
      <geometry>
        <mesh
          filename="package://lunarArm/meshes/link_6.STL" />
      </geometry>
      <material
        name="">
        <color
          rgba="0.77647 0.75686 0.73725 1" />
      </material>
    </visual>
    <collision>
      <origin
        xyz="0 0 0"
        rpy="0 0 0" />
      <geometry>
        <mesh
          filename="package://lunarArm/meshes/link_6.STL" />
      </geometry>
    </collision>
  </link>
  <joint
    name="joint_6"
    type="revolute">
    <origin
      xyz="0 0.1256 0"
      rpy="-1.5708 0 0" />
    <parent
      link="link_5" />
    <child
      link="link_6" />
    <axis
      xyz="0 0 1" />
    <limit
      lower="-6.2832"
      upper="6.2832"
      effort="0"
      velocity="0" />
  </joint>
</robot>